<?xml version="1.0" encoding="utf-8"?>
<!-- This URDF was automatically created by SolidWorks to URDF Exporter! Originally created by Stephen Brawner (brawner@gmail.com) 
     Commit Version: 1.6.0-4-g7f85cfe  Build Version: 1.6.7995.38578
     For more information, please see http://wiki.ros.org/sw_urdf_exporter -->
<robot name="pcb">
  <!-- <mujoco>
        <compiler 
        angle="radian"
        meshdir="meshes/" 
        balanceinertia="true" 
        discardvisual="false" />
  </mujoco> -->
    <link name="world"></link>
  <joint name="floating_base_joint" type="floating">
    <parent link="world"/>
    <child link="base"/>
  </joint>
  <link name="base">
    <inertial>
      <origin xyz="0.015546 -0.000356 -0.002522" rpy="0 0 0" />
      <mass value="11.714" />
      <inertia ixx="0.080386100" ixy="0.000372957" ixz="-0.006899500" iyy="0.302915285" iyz="0.000215670" izz="0.353776337" />
    </inertial>
    <visual>
      <origin xyz="0 0 0" rpy="0 0 0" />
      <geometry>
        <mesh filename="meshes/base.STL" />
      </geometry>
      <material name="">
        <color rgba="0.752941176470588 0.752941176470588 0.752941176470588 1" />
      </material>
    </visual>
    <collision>
      <origin xyz="0 0 0" rpy="0 0 0" />
      <geometry>
        <box size="0.46 0.2 0.13" />
      </geometry>
    </collision>
  </link>
  <joint name="imu_joint" type="fixed">
    <parent link="base"/>
    <child link="imu_link"/>
    <origin rpy="0 0 0" xyz="0 0 0"/>
  </joint>
  <link name="imu_link">
    <inertial>
      <mass value="0.001"/>
      <origin rpy="0 0 0" xyz="0 0 0"/>
      <inertia ixx="0.0001" ixy="0" ixz="0" iyy="0.0001" iyz="0" izz="0.0001"/>
    </inertial>
    <visual>
      <origin rpy="0 0 0" xyz="0 0 0"/>
      <geometry>
        <box size="0.001 0.001 0.001"/>
      </geometry>
    </visual>
    <collision>
      <origin rpy="0 0 0" xyz="0 0 0"/>
      <geometry>
        <box size=".001 .001 .001"/>
      </geometry>
    </collision>
  </link>
  <link name="FL_hip">
    <inertial>
      <origin xyz="0.02644 0.013950 0.000001" rpy="0 0 0" />
      <mass value=" 0.093" />
      <inertia ixx="0.000040414" ixy="-0.000019029" ixz="0.000000001" iyy="0.000071294" iyz="0.000000000" izz="0.000067176" />
    </inertial>
    <visual>
      <origin xyz="0 0 0" rpy="0 0 0" />
      <geometry>
        <mesh filename="meshes/FL_hip.STL" />
      </geometry>
      <material name="">
        <color rgba="0.752941176470588 0.752941176470588 0.752941176470588 1" />
      </material>
    </visual>
    <collision>
      <origin xyz="0.05 0.065 0" rpy="1.570796326794897 0 0" />
      <geometry>
        <cylinder radius="0.036" length="0.068" />
      </geometry>
    </collision>
  </link>
  <joint name="FL_hip_joint" type="revolute">
    <origin xyz="0.25555 0.06 0" rpy="0 0 0" />
    <parent link="base" />
    <child link="FL_hip" />
    <axis xyz="1 0 0" />
    <limit lower="-0.61056" upper="0.52333" effort="30" velocity="12.6" />
  </joint>
  <link name="FL_thigh">
    <inertial>
      <origin xyz=" 0.000123 0.056481 -0.124234" rpy="0 0 0" />
      <mass value="1.461" />
      <inertia ixx="0.022683810" ixy="0.000009631" ixz="-0.000024660" iyy="0.022099520" iyz="0.003455675" izz="0.001429847" />
    </inertial>
    <visual>
      <origin xyz="0 0 0" rpy="0 0 0" />
      <geometry>
        <mesh filename="meshes/FL_thigh.STL" />
      </geometry>
      <material name="">
        <color rgba="0.752941176470588 0.752941176470588 0.752941176470588 1" />
      </material>
    </visual>
    <collision>
      <origin xyz="0 0.065 -0.1065" rpy="0.15 0 0.0" />
      <geometry>
        <box size="0.034 0.0245  0.253 " />
      </geometry>
    </collision>
  </link>
  <joint name="FL_thigh_joint" type="revolute">
    <origin xyz="0.05075 0.0298 0" rpy="0 0 0" />
    <parent link="FL_hip" />
    <child link="FL_thigh" />
    <axis xyz="0 1 0" />
    <limit lower="-2.3791" upper="3.1641" effort="45" velocity="12" />
  </joint>
  <link name="FL_calf">
    <inertial>
      <origin xyz="0.001423 0.040745 -0.221672" rpy="0 0 0" />
      <mass value="0.905" />
      <inertia ixx="0.008020317" ixy="0.000041545" ixz="-0.000117383" iyy="0.009110185" iyz="0.001263761" izz="0.001924021" />
    </inertial>
    <visual>
      <origin xyz="0 0 0" rpy="0 0 0" />
      <geometry>
        <mesh filename="meshes/FL_calf.STL" />
      </geometry>
      <material name="">
        <color rgba="0.752941176470588 0.752941176470588 0.752941176470588 1" />
      </material>
    </visual>
    <collision>
        <origin xyz="0.008 0.006 -0.12" rpy="1.570796326794897 0 0" />
        <geometry>
           <box size="0.036 0.24 0.02" />
        </geometry>
      </collision>
      <collision>
        <origin xyz="0.0 0.033 0" rpy="1.570796326794897 0 0" />
        <geometry>
          <cylinder radius="0.036" length="0.072" />
        </geometry>
    </collision>
  </link>
  <joint name="FL_calf_joint" type="revolute">
    <origin xyz="0 0.0408 -0.25" rpy="0 0 0" />
    <parent link="FL_thigh" />
    <child link="FL_calf" />
    <axis xyz="0 1 0" />
    <limit lower="-2.8609" upper="2.8609" effort="45" velocity="12" />
  </joint>
  <link name="FL_foot">
    <inertial>
      <origin xyz="0.000004 -0.006349  0.000010" rpy="0 0 0" />
      <mass value="0.400" />
      <inertia ixx="0.001420971" ixy="0.000000007" ixz="-0.000000224" iyy="0.002707982" iyz="0.000000001" izz="0.001420609" />
    </inertial>
    <visual>
      <origin xyz="0 0 0" rpy="0 0 0" />
      <geometry>
        <mesh filename="meshes/FL_foot.STL" />
      </geometry>
      <material name="">
        <color rgba="0.792156862745098 0.819607843137255 0.933333333333333 1" />
      </material>
    </visual>
    <collision>
      <origin xyz="0 0 0" rpy="0 0 0" />
      <geometry>
        <mesh filename="meshes/FL_foot.STL" />
      </geometry>
    </collision>
  </link>
  <joint name="FL_foot_joint" type="fixed">
    <origin xyz="0 0.0598 -0.26" rpy="0 0 0" />
    <parent link="FL_calf" />
    <child link="FL_foot" />
    <axis xyz="0 1 0" />
    <limit lower="-99999" upper="99999" effort="30" velocity="20" />

  </joint>
  <link name="FR_hip">
    <inertial>
      <origin xyz="0.026440 -0.013950 -0.000001" rpy="0 0 0" />
      <mass value="0.093" />
      <inertia ixx="0.000040414" ixy="0.000019029" ixz="-0.000000001" iyy="0.000071294" iyz="0.000000000" izz="0.000067176" />
    </inertial>
    <visual>
      <origin xyz="0 0 0" rpy="0 0 0" />
      <geometry>
        <mesh filename="meshes/FR_hip.STL" />
      </geometry>
      <material name="">
        <color rgba="0.752941176470588 0.752941176470588 0.752941176470588 1" />
      </material>
    </visual>
    <collision>
      <origin xyz="0.05 -0.065 0" rpy="1.570796326794897 0 0" />
      <geometry>
        <cylinder radius="0.036" length="0.068" />
      </geometry>
    </collision>
  </link>
  <joint name="FR_hip_joint" type="revolute">
    <origin xyz="0.25555 -0.06 0" rpy="0 0 0" />
    <parent link="base" />
    <child link="FR_hip" />
    <axis xyz="1 0 0" />
    <limit lower="-0.61056" upper="0.52333" effort="30" velocity="12.6" />
  </joint>
  <link name="FR_thigh">
    <inertial>
      <origin xyz="0.000149 -0.056439 -0.124111" rpy="0 0 0" />
      <mass value="1.459" />
      <inertia ixx="0.022664789" ixy="-0.000008421" ixz="-0.000021626" iyy="0.022081868" iyz="-0.003449870" izz="0.001427262" />
    </inertial>
    <visual>
      <origin xyz="0 0 0" rpy="0 0 0" />
      <geometry>
        <mesh filename="meshes/FR_thigh.STL" />
      </geometry>
      <material name="">
        <color rgba="0.752941176470588 0.752941176470588 0.752941176470588 1" />
      </material>
    </visual>
    <collision>
      <origin xyz="0 -0.065 -0.1065" rpy="-0.15 0 0" />
      <geometry>
         <box size="0.034 0.0245  0.253 " />
      </geometry>
    </collision>
  </link>
  <joint name="FR_thigh_joint" type="revolute">
    <origin xyz="0.05075 -0.0298 0" rpy="0 0 0" />
    <parent link="FR_hip" />
    <child link="FR_thigh" />
    <axis xyz="0 1 0" />
    <limit lower="-2.3791" upper="3.1641" effort="45" velocity="12" />
  </joint>
  <link name="FR_calf">
    <inertial>
      <origin xyz="0.001389 -0.040744 -0.221655" rpy="0 0 0" />
      <mass value="0.905" />
      <inertia ixx="0.008019448" ixy="-0.000041298" ixz="-0.000119255" iyy="0.009109919" iyz="-0.001263976" izz="0.001924687" />
    </inertial>
    <visual>
      <origin xyz="0 0 0" rpy="0 0 0" />
      <geometry>
        <mesh filename="meshes/FR_calf.STL" />
      </geometry>
      <material name="">
        <color rgba="0.752941176470588 0.752941176470588 0.752941176470588 1" />
      </material>
    </visual>
    <collision>
      <origin xyz="0.008 -0.006 -0.12" rpy="1.570796326794897 0 0" />
      <geometry>
        <box size="0.036 0.24 0.02" />
      </geometry>
    </collision>
    <collision>
      <origin xyz="0.0 -0.033 0" rpy="1.570796326794897 0 0" />
      <geometry>
        <cylinder radius="0.036" length="0.072" />
      </geometry>
    </collision>
  </link>
  <joint name="FR_calf_joint" type="revolute">
    <origin xyz="0 -0.0408 -0.25" rpy="0 0 0" />
    <parent link="FR_thigh" />
    <child link="FR_calf" />
    <axis xyz="0 1 0" />
    <limit lower="-2.8609" upper="2.8609" effort="45" velocity="12" />
  </joint>
  <link name="FR_foot">
    <inertial>
      <origin xyz="0.000010 0.006349 -0.000004" rpy="0 0 0" />
      <mass value="0.400" />
      <inertia ixx="0.001420562" ixy="-0.000000006" ixz="0.000000176" iyy="0.002707982" iyz="-0.000000005" izz="0.001421019" />
    </inertial>
    <visual>
      <origin xyz="0 0 0" rpy="0 0 0" />
      <geometry>
        <mesh filename="meshes/FR_foot.STL" />
      </geometry>
      <material name="">
        <color rgba="0.792156862745098 0.819607843137255 0.933333333333333 1" />
      </material>
    </visual>
    <collision>
      <origin xyz="0 0 0" rpy="0 0 0" />
      <geometry>
        <mesh filename="meshes/FR_foot.STL" />
      </geometry>
    </collision>
  </link>
  <joint name="FR_foot_joint" type="fixed">
    <origin xyz="0 -0.0598 -0.26" rpy="0 0 0" />
    <parent link="FR_calf" />
    <child link="FR_foot" />
    <axis xyz="0 1 0" />
    <limit lower="-99999" upper="99999" effort="30" velocity="20" />
  </joint>
  <link name="RL_hip">
    <inertial>
      <origin xyz="-0.026440 0.013950 -0.000001" rpy="0 0 0" />
      <mass value="0.093" />
      <inertia ixx="0.000040414" ixy="0.000019029" ixz="0.000000001" iyy="0.000071294" iyz="0.000000000" izz="0.000067176" />
    </inertial>
    <visual>
      <origin xyz="0 0 0" rpy="0 0 0" />
      <geometry>
        <mesh filename="meshes/RL_hip.STL" />
      </geometry>
      <material name="">
        <color rgba="0.752941176470588 0.752941176470588 0.752941176470588 1" />
      </material>
    </visual>
    <collision>
        <origin xyz="-0.05 0.065 0" rpy="1.570796326794897 0 0" />
      <geometry>
        <cylinder radius="0.036" length="0.068" />
      </geometry>
    </collision>
  </link>
  <joint name="RL_hip_joint" type="revolute">
    <origin xyz="-0.25555 0.06 0" rpy="0 0 0" />
    <parent link="base" />
    <child link="RL_hip" />
    <axis xyz="1 0 0" />
    <limit lower="-0.61056" upper="0.52333" effort="30" velocity="12.6" />
  </joint>
  <link name="RL_thigh">
    <inertial>
      <origin xyz="-0.000126 0.056482 -0.124234" rpy="0 0 0" />
      <mass value="1.461" />
      <inertia ixx="0.022683927" ixy="-0.000009539" ixz="0.000024810" iyy="0.022099519" iyz="0.003455835" izz="0.001429963" />
    </inertial>
    <visual>
      <origin xyz="0 0 0" rpy="0 0 0" />
      <geometry>
        <mesh filename="meshes/RL_thigh.STL" />
      </geometry>
      <material name="">
        <color rgba="0.752941176470588 0.752941176470588 0.752941176470588 1" />
      </material>
    </visual>
    <collision>
      <origin xyz="0 0.065 -0.1065" rpy="0.15 0 0" />
      <geometry>
         <box size="0.034 0.0245  0.253 " />
      </geometry>
    </collision>
  </link>
  <joint name="RL_thigh_joint" type="revolute">
    <origin xyz="-0.05075 0.0298 0" rpy="0 0 0" />
    <parent link="RL_hip" />
    <child link="RL_thigh" />
    <axis xyz="0 1 0" />
    <limit lower="-3.1641" upper="2.3791" effort="45" velocity="12" />
  </joint>
  <link name="RL_calf">
    <inertial>
      <origin xyz="-0.001398 0.040735 -0.221655" rpy="0 0 0" />
      <mass value="0.906" />
      <inertia ixx="0.008019636" ixy="-0.000041397" ixz="0.000119276" iyy="0.009110081" iyz="0.001263960" izz="0.001924934" />
    </inertial>
    <visual>
      <origin xyz="0 0 0" rpy="0 0 0" />
      <geometry>
        <mesh filename="meshes/RL_calf.STL" />
      </geometry>
      <material name="">
        <color rgba="0.752941176470588 0.752941176470588 0.752941176470588 1" />
      </material>
    </visual>
    <collision>
       <origin xyz="-0.008 0.006 -0.12" rpy="1.570796326794897 0 0" />
      <geometry>
        <box size="0.036 0.24 0.02" />
      </geometry>
    </collision>
    <collision>
      <origin xyz="0.0 0.033 0" rpy="1.570796326794897 0 0" />
      <geometry>
        <cylinder radius="0.036" length="0.072" />
      </geometry>
    </collision>
  </link>
  <joint name="RL_calf_joint" type="revolute">
    <origin xyz="0 0.0408 -0.25" rpy="0 0 0" />
    <parent link="RL_thigh" />
    <child link="RL_calf" />
    <axis xyz="0 1 0" />
    <limit lower="-2.8609" upper="2.8609" effort="45" velocity="12" />
  </joint>
  <link name="RL_foot">
    <inertial>
      <origin xyz="-0.000008 -0.006349 0.000007" rpy="0 0 0" />
      <mass value="0.400" />
      <inertia ixx="0.001420792" ixy="0.000000002" ixz="0.000000288" iyy="0.002707982" iyz="0.000000007" izz="0.001420788" />
    </inertial>
    <visual>
      <origin xyz="0 0 0" rpy="0 0 0" />
      <geometry>
        <mesh filename="meshes/RL_foot.STL" />
      </geometry>
      <material name="">
        <color rgba="0.792156862745098 0.819607843137255 0.933333333333333 1" />
      </material>
    </visual>
    <collision>
      <origin xyz="0 0 0" rpy="0 0 0" />
      <geometry>
        <mesh filename="meshes/RL_foot.STL" />
      </geometry>
    </collision>
  </link>
  <joint name="RL_foot_joint" type="fixed">
    <origin xyz="0 0.0598 -0.26" rpy="0 0 0" />
    <parent link="RL_calf" />
    <child link="RL_foot" />
    <axis xyz="0 1 0" />
    <limit lower="-99999" upper="99999" effort="30" velocity="20" />
  </joint>
  <link name="RR_hip">
    <inertial>
      <origin xyz="-0.026440 -0.013950 0.000001" rpy="0 0 0" />
      <mass value="0.093" />
      <inertia ixx="0.000040414" ixy="-0.000019029" ixz="-0.000000001" iyy="0.000071294" iyz="0.000000000" izz="0.000067176" />
    </inertial>
    <visual>
      <origin xyz="0 0 0" rpy="0 0 0" />
      <geometry>
        <mesh filename="meshes/RR_hip.STL" />
      </geometry>
      <material name="">
        <color rgba="0.752941176470588 0.752941176470588 0.752941176470588 1" />
      </material>
    </visual>
    <collision>
      <origin xyz="-0.05 -0.065 0" rpy="1.570796326794897 0 0" />
      <geometry>
        <cylinder radius="0.036" length="0.068" />
      </geometry>
    </collision>
  </link>
  <joint name="RR_hip_joint" type="revolute">
    <origin xyz="-0.25555 -0.06 0" rpy="0 0 0" />
    <parent link="base" />
    <child link="RR_hip" />
    <axis xyz="1 0 0" />
    <limit lower="-0.61056" upper="0.52333" effort="30" velocity="12.6" />
  </joint>
  <link name="RR_thigh">
    <inertial>
      <origin xyz="-0.000124 -0.056481 -0.124236" rpy="0 0 0" />
      <mass value="1.461" />
      <inertia ixx="0.022683020" ixy="0.000009615" ixz="0.000024940" iyy="0.022098669" iyz="-0.003455703" izz="0.001429786" />
    </inertial>
    <visual>
      <origin xyz="0 0 0" rpy="0 0 0" />
      <geometry>
        <mesh filename="meshes/RR_thigh.STL" />
      </geometry>
      <material name="">
        <color rgba="0.752941176470588 0.752941176470588 0.752941176470588 1" />
      </material>
    </visual>
    <collision>
      <origin xyz="0 -0.065 -0.1065" rpy="-0.15 0 0" />
      <geometry>
         <box size="0.034 0.0245  0.253 " />
      </geometry>
    </collision>
  </link>
  <joint name="RR_thigh_joint" type="revolute">
    <origin xyz="-0.05075 -0.0298 0" rpy="0 0 0" />
    <parent link="RR_hip" />
    <child link="RR_thigh" />
    <axis xyz="0 1 0" />
    <limit lower="-3.1641" upper="2.3791" effort="45" velocity="12" />
  </joint>
  <link name="RR_calf">
    <inertial>
      <origin xyz="-0.001423 -0.040745 -0.221672" rpy="0 0 0" />
      <mass value="0.905" />
      <inertia ixx="0.008020317" ixy="0.000041545" ixz="0.000117383" iyy="0.009110185" iyz="-0.001263761" izz="0.001924021" />
    </inertial>
    <visual>
      <origin xyz="0 0 0" rpy="0 0 0" />
      <geometry>
        <mesh filename="meshes/RR_calf.STL" />
      </geometry>
      <material name="">
        <color rgba="0.752941176470588 0.752941176470588 0.752941176470588 1" />
      </material>
    </visual>
    <collision>
       <origin xyz="-0.008 -0.006 -0.12" rpy="1.570796326794897 0 0" />
      <geometry>
        <box size="0.036 0.24 0.02" />
      </geometry>
    </collision>

    <collision>
      <origin xyz="0.0 -0.033 0" rpy="1.570796326794897 0 0" />
      <geometry>
        <cylinder radius="0.036" length="0.072" />
      </geometry>
    </collision>
  </link>
  <joint name="RR_calf_joint" type="revolute">
    <origin xyz="0 -0.0408 -0.25" rpy="0 0 0" />
    <parent link="RR_thigh" />
    <child link="RR_calf" />
    <axis xyz="0 1 0" />
    <limit lower="-2.8609" upper="2.8609" effort="45" velocity="12" />
  </joint>
  <link name="RR_foot">
    <inertial>
      <origin xyz="-0.000006 0.006349 -0.000009" rpy="0 0 0" />
      <mass value="0.400" />
      <inertia ixx="0.001420894" ixy="-0.000000003" ixz="-0.000000269" iyy="0.002707982" iyz="0.000000007" izz="0.001420687" />
    </inertial>
    <visual>
      <origin xyz="0 0 0" rpy="0 0 0" />
      <geometry>
        <mesh filename="meshes/RR_foot.STL" />
      </geometry>
      <material name="">
        <color rgba="0.792156862745098 0.819607843137255 0.933333333333333 1" />
      </material>
    </visual>
    <collision>
      <origin xyz="0 0 0" rpy="0 0 0" />
      <geometry>
        <mesh filename="meshes/RR_foot.STL" />
      </geometry>
    </collision>
  </link>
  <joint name="RR_foot_joint" type="fixed">
    <origin xyz="0 -0.0598 -0.26" rpy="0 0 0" />
    <parent link="RR_calf" />
    <child link="RR_foot" />
    <axis xyz="0 1 0" />
    <limit lower="-99999" upper="99999" effort="30" velocity="20" />
  </joint>
</robot>
